<?xml version="1.0" encoding="utf-8"?>
<sdf version='1.6'>
  <model name='iris'>
    <link name='base_link'>
      <pose frame=''>0 0 0 0 -0 0</pose>
      <inertial>
        <pose frame=''>-0.137456 5e-06 0.310624 0 -0 0</pose>
        <mass>73.4785</mass>
        <inertia>
          <ixx>1.68937</ixx>
          <ixy>-2.86187e-05</ixy>
          <ixz>-0.111334</ixz>
          <iyy>3.23773</iyy>
          <iyz>-0.00648132</iyz>
          <izz>3.65573</izz>
        </inertia>
      </inertial>
      <collision name='base_link_collision'>
        <pose frame=''>0 0 0 0 -0 0</pose>
        <geometry>
          <mesh>
            <scale>1 1 1</scale>
            <uri>model://flying_car_urdf/meshes/base_link.STL</uri>
          </mesh>
        </geometry>
      </collision>
      <collision name='base_link_fixed_joint_lump__velodyne2_base_link_collision_1'>
        <pose frame=''>0.5 0 0.57212 0 -0 0</pose>
        <geometry>
          <cylinder>
            <length>0.14424</length>
            <radius>0.04267</radius>
          </cylinder>
        </geometry>
      </collision>
      <visual name='base_link_visual'>
        <pose frame=''>0 0 0 0 -0 0</pose>
        <geometry>
          <mesh>
            <scale>1 1 1</scale>
            <uri>model://flying_car_urdf/meshes/base_link.STL</uri>
          </mesh>
        </geometry>
      </visual>
      <visual name='base_link_fixed_joint_lump__visual_visual_1'>
        <pose frame=''>0.5 0 0.7 0 -0 0</pose>
        <geometry>
          <cylinder>
            <length>0.002</length>
            <radius>0.01</radius>
          </cylinder>
        </geometry>
      </visual>
      <visual name='base_link_fixed_joint_lump__velodyne2_base_link_visual_2'>
        <pose frame=''>0.5 0 0.5 0 -0 0</pose>
        <geometry>
          <mesh>
            <scale>1 1 1</scale>
            <uri>model://velodyne_description/meshes/HDL32E_base.dae</uri>
          </mesh>
        </geometry>
      </visual>
      <visual name='base_link_fixed_joint_lump__velodyne2_visual_3'>
        <pose frame=''>0.5 0 0.5 0 -0 0</pose>
        <geometry>
          <mesh>
            <scale>1 1 1</scale>
            <uri>model://velodyne_description/meshes/HDL32E_scan.dae</uri>
          </mesh>
        </geometry>
        <material>
          <script>
            <uri>__default__</uri>
            <name>__default__</name>
          </script>
        </material>
      </visual>
      <gravity>1</gravity>
      <velocity_decay/>
      <sensor name='velodyne2-HDL32E' type='ray'>
        <visualize>0</visualize>
        <update_rate>10</update_rate>
        <ray>
          <scan>
            <horizontal>
              <samples>220</samples>
              <resolution>1</resolution>
              <min_angle>-3.14159</min_angle>
              <max_angle>3.14159</max_angle>
            </horizontal>
            <vertical>
              <samples>32</samples>
              <resolution>1</resolution>
              <min_angle>-0.535292</min_angle>
              <max_angle>0.186227</max_angle>
            </vertical>
          </scan>
          <range>
            <min>0.3</min>
            <max>131</max>
            <resolution>0.001</resolution>
          </range>
          <noise>
            <type>gaussian</type>
            <mean>0</mean>
            <stddev>0</stddev>
          </noise>
        </ray>
        <plugin name='gazebo_ros_laser_controller' filename='libgazebo_ros_velodyne_laser.so'>
          <topicName>/velodyne_points2</topicName>
          <frameName>velodyne2</frameName>
          <min_range>0.9</min_range>
          <max_range>130.0</max_range>
          <gaussianNoise>0.008</gaussianNoise>
        </plugin>
        <pose frame=''>0.5 0 0.59081 0 -0 0</pose>
      </sensor>
    </link>
    <link name='FL_arm_link'>
      <pose frame=''>0.94 0.48 0.34 0 -0 1.5708</pose>
      <inertial>
        <pose frame=''>0.405693 0.003148 0.107253 0 -0 0</pose>
        <mass>3.89447</mass>
        <inertia>
          <ixx>0.0076495</ixx>
          <ixy>7.20024e-05</ixy>
          <ixz>-2.12112e-07</ixz>
          <iyy>0.033092</iyy>
          <iyz>-1.37631e-08</iyz>
          <izz>0.0321291</izz>
        </inertia>
      </inertial>
      <collision name='FL_arm_link_collision'>
        <pose frame=''>0 0 0 0 -0 0</pose>
        <geometry>
          <mesh>
            <scale>1 1 1</scale>
            <uri>model://flying_car_urdf/meshes/FL_arm_link.STL</uri>
          </mesh>
        </geometry>
      </collision>
      <visual name='FL_arm_link_visual'>
        <pose frame=''>0 0 0 0 -0 0</pose>
        <geometry>
          <mesh>
            <scale>1 1 1</scale>
            <uri>model://flying_car_urdf/meshes/FL_arm_link.STL</uri>
          </mesh>
        </geometry>
      </visual>
    </link>
    <joint name='FL_arm_joint' type='revolute'>
      <child>FL_arm_link</child>
      <parent>base_link</parent>
      <axis>
        <xyz>0 0 -1</xyz>
        <limit>
          <lower>-1.57</lower>
          <upper>0</upper>
          <effort>100</effort>
          <velocity>1</velocity>
        </limit>
        <dynamics>
          <spring_reference>0</spring_reference>
          <spring_stiffness>0</spring_stiffness>
        </dynamics>
        <use_parent_model_frame>1</use_parent_model_frame>
      </axis>
    </joint>
    <link name='FL_prop_link'>
      <pose frame=''>0.94 1.24505 0.594 1.5708 -0 1.5708</pose>
      <inertial>
        <pose frame=''>0 -0.001861 -0 0 -0 0</pose>
        <mass>1.00633</mass>
        <inertia>
          <ixx>0.0495943</ixx>
          <ixy>5.12014e-11</ixy>
          <ixz>0.0777131</ixz>
          <iyy>0.173195</iyy>
          <iyz>1.30511e-10</iyz>
          <izz>0.123701</izz>
        </inertia>
      </inertial>
      <collision name='FL_prop_link_collision'>
        <pose frame=''>0 0 0 0 -0 0</pose>
        <geometry>
          <mesh>
            <scale>1 1 1</scale>
            <uri>model://flying_car_urdf/meshes/FL_prop_link.STL</uri>
          </mesh>
        </geometry>
      </collision>
      <visual name='FL_prop_link_visual'>
        <pose frame=''>0 0 0 0 -0 0</pose>
        <geometry>
          <mesh>
            <scale>1 1 1</scale>
            <uri>model://flying_car_urdf/meshes/FL_prop_link.STL</uri>
          </mesh>
        </geometry>
      </visual>
    </link>
    <joint name='FL_prop_joint' type='revolute'>
      <child>FL_prop_link</child>
      <parent>FL_arm_link</parent>
      <axis>
        <xyz>4e-06 0 1</xyz>
        <limit>
          <lower>-1e+16</lower>
          <upper>1e+16</upper>
        </limit>
        <dynamics>
          <spring_reference>0</spring_reference>
          <spring_stiffness>0</spring_stiffness>
        </dynamics>
        <use_parent_model_frame>1</use_parent_model_frame>
      </axis>
    </joint>
    <link name='FL_steer_link'>
      <pose frame=''>0.707 0.308 0.15 0 -0 0</pose>
      <inertial>
        <pose frame=''>0 0 -0.045213 0 -0 0</pose>
        <mass>0.230273</mass>
        <inertia>
          <ixx>0.000349257</ixx>
          <ixy>1.45518e-14</ixy>
          <ixz>1.39566e-19</ixz>
          <iyy>0.000450897</iyy>
          <iyz>2.42538e-20</iyz>
          <izz>0.000182393</izz>
        </inertia>
      </inertial>
      <collision name='FL_steer_link_collision'>
        <pose frame=''>0 0 0 0 -0 0</pose>
        <geometry>
          <mesh>
            <scale>1 1 1</scale>
            <uri>model://flying_car_urdf/meshes/FL_steer_link.STL</uri>
          </mesh>
        </geometry>
      </collision>
      <visual name='FL_steer_link_visual'>
        <pose frame=''>0 0 0 0 -0 0</pose>
        <geometry>
          <mesh>
            <scale>1 1 1</scale>
            <uri>model://flying_car_urdf/meshes/FL_steer_link.STL</uri>
          </mesh>
        </geometry>
      </visual>
    </link>
    <joint name='FL_steer_joint' type='revolute'>
      <child>FL_steer_link</child>
      <parent>base_link</parent>
      <axis>
        <xyz>0 0 1</xyz>
        <limit>
          <lower>-1.57</lower>
          <upper>1.57</upper>
          <effort>1</effort>
          <velocity>1</velocity>
        </limit>
        <dynamics>
          <spring_reference>0</spring_reference>
          <spring_stiffness>0</spring_stiffness>
        </dynamics>
        <use_parent_model_frame>1</use_parent_model_frame>
      </axis>
    </joint>
    <link name='FL_wheel_link'>
      <pose frame=''>0.707 0.308 0.005 1.5708 -0 1.5708</pose>
      <inertial>
        <pose frame=''>-0 -0 0 0 -0 0</pose>
        <mass>1.84219</mass>
        <inertia>
          <ixx>0.0177302</ixx>
          <ixy>5.8538e-20</ixy>
          <ixz>3.0583e-18</ixz>
          <iyy>0.0092579</iyy>
          <iyz>-3.9272e-18</iyz>
          <izz>0.0092579</izz>
        </inertia>
      </inertial>
      <collision name='FL_wheel_link_collision'>
        <pose frame=''>0 0 0 0 -0 0</pose>
        <geometry>
          <mesh>
            <scale>1 1 1</scale>
            <uri>model://flying_car_urdf/meshes/FL_wheel_link.STL</uri>
          </mesh>
        </geometry>
      </collision>
      <visual name='FL_wheel_link_visual'>
        <pose frame=''>0 0 0 0 -0 0</pose>
        <geometry>
          <mesh>
            <scale>1 1 1</scale>
            <uri>model://flying_car_urdf/meshes/FL_wheel_link.STL</uri>
          </mesh>
        </geometry>
      </visual>
    </link>
    <joint name='FL_wheel_joint' type='revolute'>
      <child>FL_wheel_link</child>
      <parent>FL_steer_link</parent>
      <axis>
        <xyz>0 -1 -0</xyz>
        <limit>
          <lower>-1e+16</lower>
          <upper>1e+16</upper>
        </limit>
        <dynamics>
          <spring_reference>0</spring_reference>
          <spring_stiffness>0</spring_stiffness>
        </dynamics>
        <use_parent_model_frame>1</use_parent_model_frame>
      </axis>
    </joint>
    <link name='FR_arm_link'>
      <pose frame=''>0.94 -0.48 0.44 -1.5708 -0 -1.5708</pose>
      <inertial>
        <pose frame=''>0.405693 -0.007253 -0.003148 0 -0 0</pose>
        <mass>3.89447</mass>
        <inertia>
          <ixx>0.0076495</ixx>
          <ixy>2.12112e-07</ixy>
          <ixz>-7.20022e-05</ixz>
          <iyy>0.0321291</iyy>
          <iyz>1.37631e-08</iyz>
          <izz>0.033092</izz>
        </inertia>
      </inertial>
      <collision name='FR_arm_link_collision'>
        <pose frame=''>0 0 0 0 -0 0</pose>
        <geometry>
          <mesh>
            <scale>1 1 1</scale>
            <uri>model://flying_car_urdf/meshes/FR_arm_link.STL</uri>
          </mesh>
        </geometry>
      </collision>
      <visual name='FR_arm_link_visual'>
        <pose frame=''>0 0 0 0 -0 0</pose>
        <geometry>
          <mesh>
            <scale>1 1 1</scale>
            <uri>model://flying_car_urdf/meshes/FR_arm_link.STL</uri>
          </mesh>
        </geometry>
      </visual>
    </link>
    <joint name='FR_arm_joint' type='revolute'>
      <child>FR_arm_link</child>
      <parent>base_link</parent>
      <axis>
        <xyz>4e-06 -0 1</xyz>
        <limit>
          <lower>-1.57</lower>
          <upper>0</upper>
          <effort>100</effort>
          <velocity>1</velocity>
        </limit>
        <dynamics>
          <spring_reference>0</spring_reference>
          <spring_stiffness>0</spring_stiffness>
        </dynamics>
        <use_parent_model_frame>1</use_parent_model_frame>
      </axis>
    </joint>
    <link name='FR_prop_link'>
      <pose frame=''>0.939998 -1.24505 0.594 1.5708 0 1.57079</pose>
      <inertial>
        <pose frame=''>-0 -0.001861 0 0 -0 0</pose>
        <mass>1.00636</mass>
        <inertia>
          <ixx>0.0395702</ixx>
          <ixy>4.88904e-10</ixy>
          <ixz>0.0720874</ixz>
          <iyy>0.173211</iyy>
          <iyz>-1.15462e-10</iyz>
          <izz>0.133741</izz>
        </inertia>
      </inertial>
      <collision name='FR_prop_link_collision'>
        <pose frame=''>0 0 0 0 -0 0</pose>
        <geometry>
          <mesh>
            <scale>1 1 1</scale>
            <uri>model://flying_car_urdf/meshes/FR_prop_link.STL</uri>
          </mesh>
        </geometry>
      </collision>
      <visual name='FR_prop_link_visual'>
        <pose frame=''>0 0 0 0 -0 0</pose>
        <geometry>
          <mesh>
            <scale>1 1 1</scale>
            <uri>model://flying_car_urdf/meshes/FR_prop_link.STL</uri>
          </mesh>
        </geometry>
      </visual>
    </link>
    <joint name='FR_prop_joint' type='revolute'>
      <child>FR_prop_link</child>
      <parent>FR_arm_link</parent>
      <axis>
        <xyz>4e-06 -0 1</xyz>
        <limit>
          <lower>-1e+16</lower>
          <upper>1e+16</upper>
        </limit>
        <dynamics>
          <spring_reference>0</spring_reference>
          <spring_stiffness>0</spring_stiffness>
        </dynamics>
        <use_parent_model_frame>1</use_parent_model_frame>
      </axis>
    </joint>
    <link name='FR_steer_link'>
      <pose frame=''>0.707 -0.308 0.15 0 -0 0</pose>
      <inertial>
        <pose frame=''>-0 0 -0.045213 0 -0 0</pose>
        <mass>0.230273</mass>
        <inertia>
          <ixx>0.000349257</ixx>
          <ixy>1.45518e-14</ixy>
          <ixz>-7.92478e-19</ixz>
          <iyy>0.000450897</iyy>
          <iyz>1.54271e-20</iyz>
          <izz>0.000182393</izz>
        </inertia>
      </inertial>
      <collision name='FR_steer_link_collision'>
        <pose frame=''>0 0 0 0 -0 0</pose>
        <geometry>
          <mesh>
            <scale>1 1 1</scale>
            <uri>model://flying_car_urdf/meshes/FR_steer_link.STL</uri>
          </mesh>
        </geometry>
      </collision>
      <visual name='FR_steer_link_visual'>
        <pose frame=''>0 0 0 0 -0 0</pose>
        <geometry>
          <mesh>
            <scale>1 1 1</scale>
            <uri>model://flying_car_urdf/meshes/FR_steer_link.STL</uri>
          </mesh>
        </geometry>
      </visual>
    </link>
    <joint name='FR_steer_joint' type='revolute'>
      <child>FR_steer_link</child>
      <parent>base_link</parent>
      <axis>
        <xyz>0 0 1</xyz>
        <limit>
          <lower>-1.57</lower>
          <upper>1.57</upper>
          <effort>1</effort>
          <velocity>1</velocity>
        </limit>
        <dynamics>
          <spring_reference>0</spring_reference>
          <spring_stiffness>0</spring_stiffness>
        </dynamics>
        <use_parent_model_frame>1</use_parent_model_frame>
      </axis>
    </joint>
    <link name='FR_wheel_link'>
      <pose frame=''>0.707 -0.308 0.005 1.5708 -0 1.5708</pose>
      <inertial>
        <pose frame=''>-0 -0 0 0 -0 0</pose>
        <mass>1.84219</mass>
        <inertia>
          <ixx>0.0177302</ixx>
          <ixy>-4.28723e-19</ixy>
          <ixz>2.20679e-18</ixz>
          <iyy>0.0092579</iyy>
          <iyz>-3.12343e-18</iyz>
          <izz>0.0092579</izz>
        </inertia>
      </inertial>
      <collision name='FR_wheel_link_collision'>
        <pose frame=''>0 0 0 0 -0 0</pose>
        <geometry>
          <mesh>
            <scale>1 1 1</scale>
            <uri>model://flying_car_urdf/meshes/FR_wheel_link.STL</uri>
          </mesh>
        </geometry>
      </collision>
      <visual name='FR_wheel_link_visual'>
        <pose frame=''>0 0 0 0 -0 0</pose>
        <geometry>
          <mesh>
            <scale>1 1 1</scale>
            <uri>model://flying_car_urdf/meshes/FR_wheel_link.STL</uri>
          </mesh>
        </geometry>
      </visual>
    </link>
    <joint name='FR_wheel_joint' type='revolute'>
      <child>FR_wheel_link</child>
      <parent>FR_steer_link</parent>
      <axis>
        <xyz>-0 1 0</xyz>
        <limit>
          <lower>-1e+16</lower>
          <upper>1e+16</upper>
        </limit>
        <dynamics>
          <spring_reference>0</spring_reference>
          <spring_stiffness>0</spring_stiffness>
        </dynamics>
        <use_parent_model_frame>1</use_parent_model_frame>
      </axis>
    </joint>
    <link name='RL_arm_link'>
      <pose frame=''>-0.94 0.48 0.44 1.5708 -0 1.5708</pose>
      <inertial>
        <pose frame=''>0.405693 0.007253 0.003148 0 -0 0</pose>
        <mass>3.89447</mass>
        <inertia>
          <ixx>0.0076495</ixx>
          <ixy>-2.12112e-07</ixy>
          <ixz>7.20022e-05</ixz>
          <iyy>0.0321291</iyy>
          <iyz>1.37631e-08</iyz>
          <izz>0.033092</izz>
        </inertia>
      </inertial>
      <collision name='RL_arm_link_collision'>
        <pose frame=''>0 0 0 0 -0 0</pose>
        <geometry>
          <mesh>
            <scale>1 1 1</scale>
            <uri>model://flying_car_urdf/meshes/RL_arm_link.STL</uri>
          </mesh>
        </geometry>
      </collision>
      <visual name='RL_arm_link_visual'>
        <pose frame=''>0 0 0 0 -0 0</pose>
        <geometry>
          <mesh>
            <scale>1 1 1</scale>
            <uri>model://flying_car_urdf/meshes/RL_arm_link.STL</uri>
          </mesh>
        </geometry>
      </visual>
    </link>
    <joint name='RL_arm_joint' type='revolute'>
      <child>RL_arm_link</child>
      <parent>base_link</parent>
      <axis>
        <xyz>4e-06 0 1</xyz>
        <limit>
          <lower>-1.57</lower>
          <upper>0</upper>
          <effort>100</effort>
          <velocity>1</velocity>
        </limit>
        <dynamics>
          <spring_reference>0</spring_reference>
          <spring_stiffness>0</spring_stiffness>
        </dynamics>
        <use_parent_model_frame>1</use_parent_model_frame>
      </axis>
    </joint>
    <link name='RL_prop_link'>
      <pose frame=''>-0.940002 1.24505 0.594 1.5708 -0 1.5708</pose>
      <inertial>
        <pose frame=''>-0 -0.001861 0 0 -0 0</pose>
        <mass>1.00636</mass>
        <inertia>
          <ixx>0.0395702</ixx>
          <ixy>5.373e-10</ixy>
          <ixz>0.0720874</ixz>
          <iyy>0.173211</iyy>
          <iyz>-1.3654e-10</iyz>
          <izz>0.133741</izz>
        </inertia>
      </inertial>
      <collision name='RL_prop_link_collision'>
        <pose frame=''>0 0 0 0 -0 0</pose>
        <geometry>
          <mesh>
            <scale>1 1 1</scale>
            <uri>model://flying_car_urdf/meshes/RL_prop_link.STL</uri>
          </mesh>
        </geometry>
      </collision>
      <visual name='RL_prop_link_visual'>
        <pose frame=''>0 0 0 0 -0 0</pose>
        <geometry>
          <mesh>
            <scale>1 1 1</scale>
            <uri>model://flying_car_urdf/meshes/RL_prop_link.STL</uri>
          </mesh>
        </geometry>
      </visual>
    </link>
    <joint name='RL_prop_joint' type='revolute'>
      <child>RL_prop_link</child>
      <parent>RL_arm_link</parent>
      <axis>
        <xyz>4e-06 0 1</xyz>
        <limit>
          <lower>-1e+16</lower>
          <upper>1e+16</upper>
        </limit>
        <dynamics>
          <spring_reference>0</spring_reference>
          <spring_stiffness>0</spring_stiffness>
        </dynamics>
        <use_parent_model_frame>1</use_parent_model_frame>
      </axis>
    </joint>
    <link name='RL_steer_link'>
      <pose frame=''>-0.707 0.308 0.15 0 -0 0</pose>
      <inertial>
        <pose frame=''>0 -0 -0.045213 0 -0 0</pose>
        <mass>0.230273</mass>
        <inertia>
          <ixx>0.000349257</ixx>
          <ixy>1.45516e-14</ixy>
          <ixz>-2.9833e-20</ixz>
          <iyy>0.000450897</iyy>
          <iyz>3.99501e-20</iyz>
          <izz>0.000182393</izz>
        </inertia>
      </inertial>
      <collision name='RL_steer_link_collision'>
        <pose frame=''>0 0 0 0 -0 0</pose>
        <geometry>
          <mesh>
            <scale>1 1 1</scale>
            <uri>model://flying_car_urdf/meshes/RL_steer_link.STL</uri>
          </mesh>
        </geometry>
      </collision>
      <visual name='RL_steer_link_visual'>
        <pose frame=''>0 0 0 0 -0 0</pose>
        <geometry>
          <mesh>
            <scale>1 1 1</scale>
            <uri>model://flying_car_urdf/meshes/RL_steer_link.STL</uri>
          </mesh>
        </geometry>
      </visual>
    </link>
    <joint name='RL_steer_joint' type='revolute'>
      <child>RL_steer_link</child>
      <parent>base_link</parent>
      <axis>
        <xyz>0 0 1</xyz>
        <limit>
          <lower>0</lower>
          <upper>0</upper>
          <effort>0</effort>
          <velocity>0</velocity>
        </limit>
        <dynamics>
          <spring_reference>0</spring_reference>
          <spring_stiffness>0</spring_stiffness>
        </dynamics>
        <use_parent_model_frame>1</use_parent_model_frame>
      </axis>
    </joint>
    <link name='RL_wheel_link'>
      <pose frame=''>-0.707 0.3085 0.005 1.5708 -0 1.5708</pose>
      <inertial>
        <pose frame=''>-0 0 -0 0 -0 0</pose>
        <mass>1.84219</mass>
        <inertia>
          <ixx>0.0177302</ixx>
          <ixy>1.75741e-19</ixy>
          <ixz>-3.86956e-18</ixz>
          <iyy>0.0092579</iyy>
          <iyz>-1.63877e-18</iyz>
          <izz>0.0092579</izz>
        </inertia>
      </inertial>
      <collision name='RL_wheel_link_collision'>
        <pose frame=''>0 0 0 0 -0 0</pose>
        <geometry>
          <mesh>
            <scale>1 1 1</scale>
            <uri>model://flying_car_urdf/meshes/RL_wheel_link.STL</uri>
          </mesh>
        </geometry>
      </collision>
      <visual name='RL_wheel_link_visual'>
        <pose frame=''>0 0 0 0 -0 0</pose>
        <geometry>
          <mesh>
            <scale>1 1 1</scale>
            <uri>model://flying_car_urdf/meshes/RL_wheel_link.STL</uri>
          </mesh>
        </geometry>
      </visual>
    </link>
    <joint name='RL_wheel_joint' type='revolute'>
      <child>RL_wheel_link</child>
      <parent>RL_steer_link</parent>
      <axis>
        <xyz>-0 1 0</xyz>
        <limit>
          <lower>-1e+16</lower>
          <upper>1e+16</upper>
        </limit>
        <dynamics>
          <spring_reference>0</spring_reference>
          <spring_stiffness>0</spring_stiffness>
        </dynamics>
        <use_parent_model_frame>1</use_parent_model_frame>
      </axis>
    </joint>
    <link name='RR_arm_link'>
      <pose frame=''>-0.94 -0.48 0.34 0 0 -1.5708</pose>
      <inertial>
        <pose frame=''>0.405693 0.003148 0.107253 0 -0 0</pose>
        <mass>3.89447</mass>
        <inertia>
          <ixx>0.0076495</ixx>
          <ixy>7.20024e-05</ixy>
          <ixz>-2.12112e-07</ixz>
          <iyy>0.033092</iyy>
          <iyz>-1.37631e-08</iyz>
          <izz>0.0321291</izz>
        </inertia>
      </inertial>
      <collision name='RR_arm_link_collision'>
        <pose frame=''>0 0 0 0 -0 0</pose>
        <geometry>
          <mesh>
            <scale>1 1 1</scale>
            <uri>model://flying_car_urdf/meshes/RR_arm_link.STL</uri>
          </mesh>
        </geometry>
      </collision>
      <visual name='RR_arm_link_visual'>
        <pose frame=''>0 0 0 0 -0 0</pose>
        <geometry>
          <mesh>
            <scale>1 1 1</scale>
            <uri>model://flying_car_urdf/meshes/RR_arm_link.STL</uri>
          </mesh>
        </geometry>
      </visual>
    </link>
    <joint name='RR_arm_joint' type='revolute'>
      <child>RR_arm_link</child>
      <parent>base_link</parent>
      <axis>
        <xyz>0 0 -1</xyz>
        <limit>
          <lower>-1.57</lower>
          <upper>0</upper>
          <effort>100</effort>
          <velocity>1</velocity>
        </limit>
        <dynamics>
          <spring_reference>0</spring_reference>
          <spring_stiffness>0</spring_stiffness>
        </dynamics>
        <use_parent_model_frame>1</use_parent_model_frame>
      </axis>
    </joint>
    <link name='RR_prop_link'>
      <pose frame=''>-0.940003 -1.24505 0.594 1.5708 -0 1.57079</pose>
      <inertial>
        <pose frame=''>0 -0.001861 -0 0 -0 0</pose>
        <mass>1.00633</mass>
        <inertia>
          <ixx>0.0495943</ixx>
          <ixy>-5.63369e-11</ixy>
          <ixz>0.0777131</ixz>
          <iyy>0.173195</iyy>
          <iyz>2.46589e-10</iyz>
          <izz>0.123701</izz>
        </inertia>
      </inertial>
      <collision name='RR_prop_link_collision'>
        <pose frame=''>0 0 0 0 -0 0</pose>
        <geometry>
          <mesh>
            <scale>1 1 1</scale>
            <uri>model://flying_car_urdf/meshes/RR_prop_link.STL</uri>
          </mesh>
        </geometry>
      </collision>
      <visual name='RR_prop_link_visual'>
        <pose frame=''>0 0 0 0 -0 0</pose>
        <geometry>
          <mesh>
            <scale>1 1 1</scale>
            <uri>model://flying_car_urdf/meshes/RR_prop_link.STL</uri>
          </mesh>
        </geometry>
      </visual>
    </link>
    <joint name='RR_prop_joint' type='revolute'>
      <child>RR_prop_link</child>
      <parent>RR_arm_link</parent>
      <axis>
        <xyz>0 0 1</xyz>
        <limit>
          <lower>-1e+16</lower>
          <upper>1e+16</upper>
        </limit>
        <dynamics>
          <spring_reference>0</spring_reference>
          <spring_stiffness>0</spring_stiffness>
        </dynamics>
        <use_parent_model_frame>1</use_parent_model_frame>
      </axis>
    </joint>
    <link name='RR_steer_link'>
      <pose frame=''>-0.707 -0.308 0.15 0 -0 0</pose>
      <inertial>
        <pose frame=''>0 0 -0.045213 0 -0 0</pose>
        <mass>0.230273</mass>
        <inertia>
          <ixx>0.000349257</ixx>
          <ixy>1.45517e-14</ixy>
          <ixz>2.46153e-19</ixz>
          <iyy>0.000450897</iyy>
          <iyz>3.50516e-22</iyz>
          <izz>0.000182393</izz>
        </inertia>
      </inertial>
      <collision name='RR_steer_link_collision'>
        <pose frame=''>0 0 0 0 -0 0</pose>
        <geometry>
          <mesh>
            <scale>1 1 1</scale>
            <uri>model://flying_car_urdf/meshes/RR_steer_link.STL</uri>
          </mesh>
        </geometry>
      </collision>
      <visual name='RR_steer_link_visual'>
        <pose frame=''>0 0 0 0 -0 0</pose>
        <geometry>
          <mesh>
            <scale>1 1 1</scale>
            <uri>model://flying_car_urdf/meshes/RR_steer_link.STL</uri>
          </mesh>
        </geometry>
      </visual>
    </link>
    <joint name='RR_steer_joint' type='revolute'>
      <child>RR_steer_link</child>
      <parent>base_link</parent>
      <axis>
        <xyz>0 0 1</xyz>
        <limit>
          <lower>0</lower>
          <upper>0</upper>
          <effort>0</effort>
          <velocity>0</velocity>
        </limit>
        <dynamics>
          <spring_reference>0</spring_reference>
          <spring_stiffness>0</spring_stiffness>
        </dynamics>
        <use_parent_model_frame>1</use_parent_model_frame>
      </axis>
    </joint>
    <link name='RR_wheel_link'>
      <pose frame=''>-0.707 -0.308 0.005 1.5708 -0 1.5708</pose>
      <inertial>
        <pose frame=''>0 0 -0 0 -0 0</pose>
        <mass>1.84219</mass>
        <inertia>
          <ixx>0.0177302</ixx>
          <ixy>-1.19673e-18</ixy>
          <ixz>9.76883e-19</ixz>
          <iyy>0.0092579</iyy>
          <iyz>-2.48054e-18</iyz>
          <izz>0.0092579</izz>
        </inertia>
      </inertial>
      <collision name='RR_wheel_link_collision'>
        <pose frame=''>0 0 0 0 -0 0</pose>
        <geometry>
          <mesh>
            <scale>1 1 1</scale>
            <uri>model://flying_car_urdf/meshes/RR_wheel_link.STL</uri>
          </mesh>
        </geometry>
      </collision>
      <visual name='RR_wheel_link_visual'>
        <pose frame=''>0 0 0 0 -0 0</pose>
        <geometry>
          <mesh>
            <scale>1 1 1</scale>
            <uri>model://flying_car_urdf/meshes/RR_wheel_link.STL</uri>
          </mesh>
        </geometry>
      </visual>
    </link>
    <joint name='RR_wheel_joint' type='revolute'>
      <child>RR_wheel_link</child>
      <parent>RR_steer_link</parent>
      <axis>
        <xyz>-0 1 0</xyz>
        <limit>
          <lower>-1e+16</lower>
          <upper>1e+16</upper>
        </limit>
        <dynamics>
          <spring_reference>0</spring_reference>
          <spring_stiffness>0</spring_stiffness>
        </dynamics>
        <use_parent_model_frame>1</use_parent_model_frame>
      </axis>
    </joint>
    <static>0</static>
    <plugin name='gazebo_ros_control' filename='libgazebo_ros_control.so'>
      <robotSimType>gazebo_ros_control/DefaultRobotHWSim</robotSimType>
    </plugin>
  </model>
</sdf>
