<?xml version="1.0" encoding="utf-8"?>
<!-- This URDF was automatically created by SolidWorks to URDF Exporter! Originally created by Stephen Brawner (brawner@gmail.com) 
     Commit Version: 1.6.0-1-g15f4949  Build Version: 1.6.7594.29634
     For more information, please see http://wiki.ros.org/sw_urdf_exporter -->
<robot name="flying_car_urdf" xmlns:xacro="http://ros.org/wiki/xacro">
  <xacro:include filename="$(find flying_car_urdf)/urdf/flying_car.gazebo.xacro"/>
  <link
    name="base_link">
    <inertial>
      <origin
        xyz="-0.146429923355639 4.6141216103468E-06 0.306922339438389"
        rpy="0 0 0" />
      <mass
        value="72.4585171289715" />
      <inertia
        ixx="1.61550819650369"
        ixy="-3.16188395392895E-05"
        ixz="0.0620334640597006"
        iyy="2.74355272384867"
        iyz="-0.00648256065496445"
        izz="3.23450546919946" />
    </inertial>
    <visual>
      <origin
        xyz="0 0 0"
        rpy="0 0 0" />
      <geometry>
        <mesh
          filename="package://flying_car_urdf/meshes/base_link.STL" />
      </geometry>
      <material
        name="">
        <color
          rgba="0.752941176470588 0.752941176470588 0.752941176470588 1" />
      </material>
    </visual>
    <collision>
      <origin
        xyz="0 0 0"
        rpy="0 0 0" />
      <geometry>
        <mesh
          filename="package://flying_car_urdf/meshes/base_link.STL" />
      </geometry>
    </collision>
  </link>
  <link
    name="FL_arm_link">
    <inertial>
      <origin
        xyz="0.405693257704713 0.0031481565089142 0.107253489414463"
        rpy="0 0 0" />
      <mass
        value="3.89447230721183" />
      <inertia
        ixx="0.00764950499387066"
        ixy="7.20024305750638E-05"
        ixz="-2.12112386887157E-07"
        iyy="0.0330920443295484"
        iyz="-1.37630637299853E-08"
        izz="0.0321291032185021" />
    </inertial>
    <visual>
      <origin
        xyz="0 0 0"
        rpy="0 0 0" />
      <geometry>
        <mesh
          filename="package://flying_car_urdf/meshes/FL_arm_link.STL" />
      </geometry>
      <material
        name="">
        <color
          rgba="0.752941176470588 0.752941176470588 0.752941176470588 1" />
      </material>
    </visual>
    <collision>
      <origin
        xyz="0 0 0"
        rpy="0 0 0" />
      <geometry>
        <mesh
          filename="package://flying_car_urdf/meshes/FL_arm_link.STL" />
      </geometry>
    </collision>
  </link>
  <joint
    name="FL_arm_joint"
    type="revolute">
    <origin
      xyz="0.940000000000001 0.48 0.339999999999999"
      rpy="0 0 1.5707963267949" />
    <parent
      link="base_link" />
    <child
      link="FL_arm_link" />
    <axis
      xyz="0 0 -1" />
    <limit
      lower="-1.57"
      upper="0"
      effort="1"
      velocity="1" />
  </joint>
  <link
    name="FL_prop_link">
    <inertial>
      <origin
        xyz="7.9164959032596E-09 -0.00186087352819841 -1.45022256425875E-08"
        rpy="0 0 0" />
      <mass
        value="1.00633319200359" />
      <inertia
        ixx="0.0495943276929438"
        ixy="5.12014239400693E-11"
        ixz="0.0777130986532108"
        iyy="0.173195440429717"
        iyz="1.30510821163399E-10"
        izz="0.123701063238782" />
    </inertial>
    <visual>
      <origin
        xyz="0 0 0"
        rpy="0 0 0" />
      <geometry>
        <mesh
          filename="package://flying_car_urdf/meshes/FL_prop_link.STL" />
      </geometry>
      <material
        name="">
        <color
          rgba="1 1 1 1" />
      </material>
    </visual>
    <collision>
      <origin
        xyz="0 0 0"
        rpy="0 0 0" />
      <geometry>
        <mesh
          filename="package://flying_car_urdf/meshes/FL_prop_link.STL" />
      </geometry>
    </collision>
  </link>
  <joint
    name="FL_prop_link"
    type="revolute">
    <origin
      xyz="0.76505 0 0.254"
      rpy="1.5708 0 0" />
    <parent
      link="FL_arm_link" />
    <child
      link="FL_prop_link" />
    <axis
      xyz="0 1 0" />
    <limit
      lower="0"
      upper="0"
      effort="0"
      velocity="0" />
  </joint>
  <link
    name="FR_arm_link">
    <inertial>
      <origin
        xyz="0.405693257704711 -0.00725348941446158 -0.00314828941180689"
        rpy="0 0 0" />
      <mass
        value="3.89447230721182" />
      <inertia
        ixx="0.00764950499387065"
        ixy="2.12112386890709E-07"
        ixz="-7.20021868805378E-05"
        iyy="0.0321291032185021"
        iyz="1.37630637386484E-08"
        izz="0.0330920443295484" />
    </inertial>
    <visual>
      <origin
        xyz="0 0 0"
        rpy="0 0 0" />
      <geometry>
        <mesh
          filename="package://flying_car_urdf/meshes/FR_arm_link.STL" />
      </geometry>
      <material
        name="">
        <color
          rgba="0.752941176470588 0.752941176470588 0.752941176470588 1" />
      </material>
    </visual>
    <collision>
      <origin
        xyz="0 0 0"
        rpy="0 0 0" />
      <geometry>
        <mesh
          filename="package://flying_car_urdf/meshes/FR_arm_link.STL" />
      </geometry>
    </collision>
  </link>
  <joint
    name="FR_arm_joint"
    type="revolute">
    <origin
      xyz="0.94 -0.48 0.44"
      rpy="-1.5708 0 -1.5708" />
    <parent
      link="base_link" />
    <child
      link="FR_arm_link" />
    <axis
      xyz="0 -1 0" />
    <limit
      lower="0"
      upper="0"
      effort="0"
      velocity="0" />
  </joint>
  <link
    name="FR_prop_link">
    <inertial>
      <origin
        xyz="-1.95864401566527E-07 -0.00186086168514299 1.01704304089623E-07"
        rpy="0 0 0" />
      <mass
        value="1.00636259561687" />
      <inertia
        ixx="0.0395701881672427"
        ixy="4.88903964209589E-10"
        ixz="0.0720874245458485"
        iyy="0.173211048789436"
        iyz="-1.15461644657509E-10"
        izz="0.133740813319805" />
    </inertial>
    <visual>
      <origin
        xyz="0 0 0"
        rpy="0 0 0" />
      <geometry>
        <mesh
          filename="package://flying_car_urdf/meshes/FR_prop_link.STL" />
      </geometry>
      <material
        name="">
        <color
          rgba="1 1 1 1" />
      </material>
    </visual>
    <collision>
      <origin
        xyz="0 0 0"
        rpy="0 0 0" />
      <geometry>
        <mesh
          filename="package://flying_car_urdf/meshes/FR_prop_link.STL" />
      </geometry>
    </collision>
  </link>
  <joint
    name="FR_prop_joint"
    type="continuous">
    <origin
      xyz="0.765051653365603 -0.154000000000011 0"
      rpy="0 0 3.14159265358979" />
    <parent
      link="FR_arm_link" />
    <child
      link="FR_prop_link" />
    <axis
      xyz="0 1 0" />
  </joint>
  <link
    name="RR_arm_link">
    <inertial>
      <origin
        xyz="0.405693257704711 0.00314815650891492 0.107253489414463"
        rpy="0 0 0" />
      <mass
        value="3.89447230721182" />
      <inertia
        ixx="0.00764950499387065"
        ixy="7.20024305750679E-05"
        ixz="-2.1211238688973E-07"
        iyy="0.0330920443295484"
        iyz="-1.37630637350729E-08"
        izz="0.0321291032185021" />
    </inertial>
    <visual>
      <origin
        xyz="0 0 0"
        rpy="0 0 0" />
      <geometry>
        <mesh
          filename="package://flying_car_urdf/meshes/RR_arm_link.STL" />
      </geometry>
      <material
        name="">
        <color
          rgba="0.752941176470588 0.752941176470588 0.752941176470588 1" />
      </material>
    </visual>
    <collision>
      <origin
        xyz="0 0 0"
        rpy="0 0 0" />
      <geometry>
        <mesh
          filename="package://flying_car_urdf/meshes/RR_arm_link.STL" />
      </geometry>
    </collision>
  </link>
  <joint
    name="RR_arm_joint"
    type="revolute">
    <origin
      xyz="-0.94 -0.48 0.34"
      rpy="0 0 -1.5708" />
    <parent
      link="base_link" />
    <child
      link="RR_arm_link" />
    <axis
      xyz="0 0 -1" />
    <limit
      lower="0"
      upper="0"
      effort="0"
      velocity="0" />
  </joint>
  <link
    name="RR_prop_link">
    <inertial>
      <origin
        xyz="2.17005934749492E-09 -0.00186087212280439 -8.24081997086168E-09"
        rpy="0 0 0" />
      <mass
        value="1.00633311458426" />
      <inertia
        ixx="0.0495943271195099"
        ixy="-5.63368805909919E-11"
        ixz="0.0777130981431345"
        iyy="0.173195439404083"
        iyz="2.46588541774348E-10"
        izz="0.123701062736267" />
    </inertial>
    <visual>
      <origin
        xyz="0 0 0"
        rpy="0 0 0" />
      <geometry>
        <mesh
          filename="package://flying_car_urdf/meshes/RR_prop_link.STL" />
      </geometry>
      <material
        name="">
        <color
          rgba="1 1 1 1" />
      </material>
    </visual>
    <collision>
      <origin
        xyz="0 0 0"
        rpy="0 0 0" />
      <geometry>
        <mesh
          filename="package://flying_car_urdf/meshes/RR_prop_link.STL" />
      </geometry>
    </collision>
  </link>
  <joint
    name="RR_prop_joint"
    type="continuous">
    <origin
      xyz="0.765051653365595 0 0.254000000000003"
      rpy="1.5707963267949 0 3.14159265358979" />
    <parent
      link="RR_arm_link" />
    <child
      link="RR_prop_link" />
    <axis
      xyz="0 1 0" />
  </joint>
  <link
    name="RL_arm_link">
    <inertial>
      <origin
        xyz="0.40569325770471 0.00725348941446136 0.00314828941180623"
        rpy="0 0 0" />
      <mass
        value="3.89447230721181" />
      <inertia
        ixx="0.00764950499387061"
        ixy="-2.12112386866559E-07"
        ixz="7.20021868805221E-05"
        iyy="0.032129103218502"
        iyz="1.37630637374215E-08"
        izz="0.0330920443295484" />
    </inertial>
    <visual>
      <origin
        xyz="0 0 0"
        rpy="0 0 0" />
      <geometry>
        <mesh
          filename="package://flying_car_urdf/meshes/RL_arm_link.STL" />
      </geometry>
      <material
        name="">
        <color
          rgba="0.752941176470588 0.752941176470588 0.752941176470588 1" />
      </material>
    </visual>
    <collision>
      <origin
        xyz="0 0 0"
        rpy="0 0 0" />
      <geometry>
        <mesh
          filename="package://flying_car_urdf/meshes/RL_arm_link.STL" />
      </geometry>
    </collision>
  </link>
  <joint
    name="RL_arm_joint"
    type="revolute">
    <origin
      xyz="-0.94 0.48 0.44"
      rpy="1.5708 0 1.5708" />
    <parent
      link="base_link" />
    <child
      link="RL_arm_link" />
    <axis
      xyz="0 1 0" />
    <limit
      lower="0"
      upper="0"
      effort="0"
      velocity="0" />
  </joint>
  <link
    name="RL_prop_link">
    <inertial>
      <origin
        xyz="-1.90695036650368E-07 -0.00186086500205929 9.97787533985051E-08"
        rpy="0 0 0" />
      <mass
        value="1.00636280361878" />
      <inertia
        ixx="0.0395701883931864"
        ixy="5.37299574939007E-10"
        ixz="0.0720874251910353"
        iyy="0.173211051383078"
        iyz="-1.36539842148325E-10"
        izz="0.133740815794897" />
    </inertial>
    <visual>
      <origin
        xyz="0 0 0"
        rpy="0 0 0" />
      <geometry>
        <mesh
          filename="package://flying_car_urdf/meshes/RL_prop_link.STL" />
      </geometry>
      <material
        name="">
        <color
          rgba="1 1 1 1" />
      </material>
    </visual>
    <collision>
      <origin
        xyz="0 0 0"
        rpy="0 0 0" />
      <geometry>
        <mesh
          filename="package://flying_car_urdf/meshes/RL_prop_link.STL" />
      </geometry>
    </collision>
  </link>
  <joint
    name="RL_prop_joint"
    type="continuous">
    <origin
      xyz="0.765051653365595 0.154000000000009 0"
      rpy="0 0 0" />
    <parent
      link="RL_arm_link" />
    <child
      link="RL_prop_link" />
    <axis
      xyz="0 1 0" />
  </joint>
  <link
    name="FR_steer_link">
    <inertial>
      <origin
        xyz="-2.22044604925031E-16 1.11022302462516E-16 -0.0452127836143312"
        rpy="0 0 0" />
      <mass
        value="0.230273438117984" />
      <inertia
        ixx="0.000349256798258404"
        ixy="1.45518192075896E-14"
        ixz="-7.92477996108057E-19"
        iyy="0.000450897154400186"
        iyz="1.54271030766644E-20"
        izz="0.000182392582849012" />
    </inertial>
    <visual>
      <origin
        xyz="0 0 0"
        rpy="0 0 0" />
      <geometry>
        <mesh
          filename="package://flying_car_urdf/meshes/FR_steer_link.STL" />
      </geometry>
      <material
        name="">
        <color
          rgba="0.752941176470588 0.752941176470588 0.752941176470588 1" />
      </material>
    </visual>
    <collision>
      <origin
        xyz="0 0 0"
        rpy="0 0 0" />
      <geometry>
        <mesh
          filename="package://flying_car_urdf/meshes/FR_steer_link.STL" />
      </geometry>
    </collision>
  </link>
  <joint
    name="FR_steer_joint"
    type="revolute">
    <origin
      xyz="0.707 -0.308 0.15"
      rpy="0 0 0" />
    <parent
      link="base_link" />
    <child
      link="FR_steer_link" />
    <axis
      xyz="0 0 1" />
    <limit
      lower="-1.57"
      upper="1.57"
      effort="1"
      velocity="1" />
  </joint>
  <link
    name="FR_wheel_link">
    <inertial>
      <origin
        xyz="-1.11022302462516E-16 -1.11022302462516E-16 0"
        rpy="0 0 0" />
      <mass
        value="1.84219192629543" />
      <inertia
        ixx="0.0177302468286368"
        ixy="-4.28723099915728E-19"
        ixz="2.20679460797186E-18"
        iyy="0.00925790244280525"
        iyz="-3.12343399300023E-18"
        izz="0.00925790244280525" />
    </inertial>
    <visual>
      <origin
        xyz="0 0 0"
        rpy="0 0 0" />
      <geometry>
        <mesh
          filename="package://flying_car_urdf/meshes/FR_wheel_link.STL" />
      </geometry>
      <material
        name="">
        <color
          rgba="0.647058823529412 0.619607843137255 0.588235294117647 1" />
      </material>
    </visual>
    <collision>
      <origin
        xyz="0 0 0"
        rpy="0 0 0" />
      <geometry>
        <mesh
          filename="package://flying_car_urdf/meshes/FR_wheel_link.STL" />
      </geometry>
    </collision>
  </link>
  <joint
    name="FR_wheel_joint"
    type="continuous">
    <origin
      xyz="0 0 -0.145000000000282"
      rpy="1.5707963267949 0 1.5707963267949" />
    <parent
      link="FR_steer_link" />
    <child
      link="FR_wheel_link" />
    <axis
      xyz="1 0 0" />
  </joint>
  <link
    name="FL_steer_link">
    <inertial>
      <origin
        xyz="0 2.22044604925031E-16 -0.0452127836143308"
        rpy="0 0 0" />
      <mass
        value="0.230273438117982" />
      <inertia
        ixx="0.000349256798258392"
        ixy="1.45517583247674E-14"
        ixz="1.39565796343945E-19"
        iyy="0.000450897154400175"
        iyz="2.4253803330348E-20"
        izz="0.000182392582849013" />
    </inertial>
    <visual>
      <origin
        xyz="0 0 0"
        rpy="0 0 0" />
      <geometry>
        <mesh
          filename="package://flying_car_urdf/meshes/FL_steer_link.STL" />
      </geometry>
      <material
        name="">
        <color
          rgba="0.752941176470588 0.752941176470588 0.752941176470588 1" />
      </material>
    </visual>
    <collision>
      <origin
        xyz="0 0 0"
        rpy="0 0 0" />
      <geometry>
        <mesh
          filename="package://flying_car_urdf/meshes/FL_steer_link.STL" />
      </geometry>
    </collision>
  </link>
  <joint
    name="FL_steer_joint"
    type="revolute">
    <origin
      xyz="0.707 0.308 0.15"
      rpy="0 0 0" />
    <parent
      link="base_link" />
    <child
      link="FL_steer_link" />
    <axis
      xyz="0 0 1" />
    <limit
      lower="-1.57"
      upper="1.57"
      effort="1"
      velocity="1" />
  </joint>
  <link
    name="FL_wheel_link">
    <inertial>
      <origin
        xyz="-2.22044604925031E-16 -1.11022302462516E-16 2.22044604925031E-16"
        rpy="0 0 0" />
      <mass
        value="1.84219192629543" />
      <inertia
        ixx="0.0177302468286368"
        ixy="5.85379655277248E-20"
        ixz="3.05830316111449E-18"
        iyy="0.00925790244280525"
        iyz="-3.92719505446036E-18"
        izz="0.00925790244280525" />
    </inertial>
    <visual>
      <origin
        xyz="0 0 0"
        rpy="0 0 0" />
      <geometry>
        <mesh
          filename="package://flying_car_urdf/meshes/FL_wheel_link.STL" />
      </geometry>
      <material
        name="">
        <color
          rgba="0.647058823529412 0.619607843137255 0.588235294117647 1" />
      </material>
    </visual>
    <collision>
      <origin
        xyz="0 0 0"
        rpy="0 0 0" />
      <geometry>
        <mesh
          filename="package://flying_car_urdf/meshes/FL_wheel_link.STL" />
      </geometry>
    </collision>
  </link>
  <joint
    name="FL_wheel_joint"
    type="continuous">
    <origin
      xyz="0 0 -0.144999999999987"
      rpy="1.5707963267949 0 1.5707963267949" />
    <parent
      link="FL_steer_link" />
    <child
      link="FL_wheel_link" />
    <axis
      xyz="-1 0 0" />
  </joint>
  <link
    name="RR_steer_link">
    <inertial>
      <origin
        xyz="3.88578058618805E-16 1.11022302462516E-16 -0.045212783614331"
        rpy="0 0 0" />
      <mass
        value="0.230273438117983" />
      <inertia
        ixx="0.000349256798258397"
        ixy="1.45517338150183E-14"
        ixz="2.46152613174949E-19"
        iyy="0.000450897154400179"
        iyz="3.50515752367294E-22"
        izz="0.000182392582849012" />
    </inertial>
    <visual>
      <origin
        xyz="0 0 0"
        rpy="0 0 0" />
      <geometry>
        <mesh
          filename="package://flying_car_urdf/meshes/RR_steer_link.STL" />
      </geometry>
      <material
        name="">
        <color
          rgba="0.752941176470588 0.752941176470588 0.752941176470588 1" />
      </material>
    </visual>
    <collision>
      <origin
        xyz="0 0 0"
        rpy="0 0 0" />
      <geometry>
        <mesh
          filename="package://flying_car_urdf/meshes/RR_steer_link.STL" />
      </geometry>
    </collision>
  </link>
  <joint
    name="RR_steer_joint"
    type="revolute">
    <origin
      xyz="-0.707 -0.308 0.15"
      rpy="0 0 0" />
    <parent
      link="base_link" />
    <child
      link="RR_steer_link" />
    <axis
      xyz="0 0 1" />
    <limit
      lower="0"
      upper="0"
      effort="0"
      velocity="0" />
  </joint>
  <link
    name="RR_wheel_link">
    <inertial>
      <origin
        xyz="0 0 -1.11022302462516E-16"
        rpy="0 0 0" />
      <mass
        value="1.84219192629543" />
      <inertia
        ixx="0.0177302468286368"
        ixy="-1.19673225549615E-18"
        ixz="9.76883033040924E-19"
        iyy="0.00925790244280525"
        iyz="-2.48053598603422E-18"
        izz="0.00925790244280525" />
    </inertial>
    <visual>
      <origin
        xyz="0 0 0"
        rpy="0 0 0" />
      <geometry>
        <mesh
          filename="package://flying_car_urdf/meshes/RR_wheel_link.STL" />
      </geometry>
      <material
        name="">
        <color
          rgba="0.647058823529412 0.619607843137255 0.588235294117647 1" />
      </material>
    </visual>
    <collision>
      <origin
        xyz="0 0 0"
        rpy="0 0 0" />
      <geometry>
        <mesh
          filename="package://flying_car_urdf/meshes/RR_wheel_link.STL" />
      </geometry>
    </collision>
  </link>
  <joint
    name="RR_wheel_joint"
    type="continuous">
    <origin
      xyz="0 0 -0.145"
      rpy="1.5707963267949 0 1.5707963267949" />
    <parent
      link="RR_steer_link" />
    <child
      link="RR_wheel_link" />
    <axis
      xyz="1 0 0" />
  </joint>
  <link
    name="RL_steer_link">
    <inertial>
      <origin
        xyz="4.44089209850063E-16 -4.44089209850063E-16 -0.0452127836146745"
        rpy="0 0 0" />
      <mass
        value="0.230273438117982" />
      <inertia
        ixx="0.000349256798258395"
        ixy="1.45516390193479E-14"
        ixz="-2.9833008345631E-20"
        iyy="0.000450897154400177"
        iyz="3.9950109397287E-20"
        izz="0.000182392582849012" />
    </inertial>
    <visual>
      <origin
        xyz="0 0 0"
        rpy="0 0 0" />
      <geometry>
        <mesh
          filename="package://flying_car_urdf/meshes/RL_steer_link.STL" />
      </geometry>
      <material
        name="">
        <color
          rgba="0.752941176470588 0.752941176470588 0.752941176470588 1" />
      </material>
    </visual>
    <collision>
      <origin
        xyz="0 0 0"
        rpy="0 0 0" />
      <geometry>
        <mesh
          filename="package://flying_car_urdf/meshes/RL_steer_link.STL" />
      </geometry>
    </collision>
  </link>
  <joint
    name="RL_steer_joint"
    type="revolute">
    <origin
      xyz="-0.707 0.307999999999994 0.150000000000006"
      rpy="0 0 0" />
    <parent
      link="base_link" />
    <child
      link="RL_steer_link" />
    <axis
      xyz="0 0 1" />
    <limit
      lower="0"
      upper="0"
      effort="0"
      velocity="0" />
  </joint>
  <link
    name="RL_wheel_link">
    <inertial>
      <origin
        xyz="-2.22044604925031E-16 0 -5.55111512312578E-17"
        rpy="0 0 0" />
      <mass
        value="1.84219192629543" />
      <inertia
        ixx="0.0177302468286368"
        ixy="1.75740894616314E-19"
        ixz="-3.86956107926909E-18"
        iyy="0.00925790244280525"
        iyz="-1.63877052492066E-18"
        izz="0.00925790244280525" />
    </inertial>
    <visual>
      <origin
        xyz="0 0 0"
        rpy="0 0 0" />
      <geometry>
        <mesh
          filename="package://flying_car_urdf/meshes/RL_wheel_link.STL" />
      </geometry>
      <material
        name="">
        <color
          rgba="0.647058823529412 0.619607843137255 0.588235294117647 1" />
      </material>
    </visual>
    <collision>
      <origin
        xyz="0 0 0"
        rpy="0 0 0" />
      <geometry>
        <mesh
          filename="package://flying_car_urdf/meshes/RL_wheel_link.STL" />
      </geometry>
    </collision>
  </link>
  <joint
    name="RL_wheel_joint"
    type="continuous">
    <origin
      xyz="0 0.000499999999971967 -0.145000000000341"
      rpy="1.5707963267949 0 1.5707963267949" />
    <parent
      link="RL_steer_link" />
    <child
      link="RL_wheel_link" />
    <axis
      xyz="1 0 0" />
  </joint>
</robot>
