<?xml version="1.0" encoding="utf-8"?>
<!-- =================================================================================== -->
<!-- |    This document was autogenerated by xacro from flying_car.urdf.xacro          | -->
<!-- |    EDITING THIS FILE BY HAND IS NOT RECOMMENDED                                 | -->
<!-- =================================================================================== -->
<!-- This URDF was automatically created by SolidWorks to URDF Exporter! Originally created by Stephen Brawner (brawner@gmail.com) 
     Commit Version: 1.6.0-1-g15f4949  Build Version: 1.6.7594.29634
     For more information, please see http://wiki.ros.org/sw_urdf_exporter -->
<!--robot name="flying_car_urdf" xmlns:xacro="http://ros.org/wiki/xacro"-->
<robot name="iris">
  <gazebo>
    <plugin filename="libgazebo_ros_control.so" name="gazebo_ros_control">
      <!--robotNamespace>/MYROBOT</robotNamespace-->
      <robotSimType>gazebo_ros_control/DefaultRobotHWSim</robotSimType>
    </plugin>
  </gazebo>
  <transmission name="tran1">
    <type>transmission_interface/SimpleTransmission</type>
    <joint name="FL_steer_joint">
      <hardwareInterface>hardware_interface/EffortJointInterface</hardwareInterface>
    </joint>
    <actuator name="motor1">
      <mechanicalReduction>1</mechanicalReduction>
    </actuator>
  </transmission>
  <transmission name="tran2">
    <type>transmission_interface/SimpleTransmission</type>
    <joint name="FR_steer_joint">
      <hardwareInterface>hardware_interface/EffortJointInterface</hardwareInterface>
    </joint>
    <actuator name="motor2">
      <mechanicalReduction>1</mechanicalReduction>
    </actuator>
  </transmission>
  <transmission name="tran3">
    <type>transmission_interface/SimpleTransmission</type>
    <joint name="FL_arm_joint">
      <hardwareInterface>hardware_interface/EffortJointInterface</hardwareInterface>
    </joint>
    <actuator name="motor3">
      <mechanicalReduction>1</mechanicalReduction>
    </actuator>
  </transmission>
  <transmission name="tran4">
    <type>transmission_interface/SimpleTransmission</type>
    <joint name="FR_arm_joint">
      <hardwareInterface>hardware_interface/EffortJointInterface</hardwareInterface>
    </joint>
    <actuator name="motor4">
      <mechanicalReduction>1</mechanicalReduction>
    </actuator>
  </transmission>
  <transmission name="tran5">
    <type>transmission_interface/SimpleTransmission</type>
    <joint name="RL_arm_joint">
      <hardwareInterface>hardware_interface/EffortJointInterface</hardwareInterface>
    </joint>
    <actuator name="motor5">
      <mechanicalReduction>1</mechanicalReduction>
    </actuator>
  </transmission>
  <transmission name="tran6">
    <type>transmission_interface/SimpleTransmission</type>
    <joint name="RR_arm_joint">
      <hardwareInterface>hardware_interface/EffortJointInterface</hardwareInterface>
    </joint>
    <actuator name="motor6">
      <mechanicalReduction>1</mechanicalReduction>
    </actuator>
  </transmission>
  <transmission name="tranFL_prop">
    <type>transmission_interface/SimpleTransmission</type>
    <joint name="FL_prop_joint">
      <hardwareInterface>hardware_interface/EffortJointInterface</hardwareInterface>
    </joint>
    <actuator name="motorFL_prop">
      <mechanicalReduction>1</mechanicalReduction>
    </actuator>
  </transmission>
  <transmission name="tranFR_prop">
    <type>transmission_interface/SimpleTransmission</type>
    <joint name="FR_prop_joint">
      <hardwareInterface>hardware_interface/EffortJointInterface</hardwareInterface>
    </joint>
    <actuator name="motorFR_prop">
      <mechanicalReduction>1</mechanicalReduction>
    </actuator>
  </transmission>
  <transmission name="tranRL_prop">
    <type>transmission_interface/SimpleTransmission</type>
    <joint name="RL_prop_joint">
      <hardwareInterface>hardware_interface/EffortJointInterface</hardwareInterface>
    </joint>
    <actuator name="motorRL_prop">
      <mechanicalReduction>1</mechanicalReduction>
    </actuator>
  </transmission>
  <transmission name="tranRR_prop">
    <type>transmission_interface/SimpleTransmission</type>
    <joint name="RR_prop_joint">
      <hardwareInterface>hardware_interface/EffortJointInterface</hardwareInterface>
    </joint>
    <actuator name="motorRR_prop">
      <mechanicalReduction>1</mechanicalReduction>
    </actuator>
  </transmission>
  <transmission name="tranFL_wheel">
    <type>transmission_interface/SimpleTransmission</type>
    <joint name="FL_wheel_joint">
      <hardwareInterface>hardware_interface/EffortJointInterface</hardwareInterface>
    </joint>
    <actuator name="FL_wheel">
      <mechanicalReduction>1</mechanicalReduction>
    </actuator>
  </transmission>
  <transmission name="tranFR_wheel">
    <type>transmission_interface/SimpleTransmission</type>
    <joint name="FR_wheel_joint">
      <hardwareInterface>hardware_interface/EffortJointInterface</hardwareInterface>
    </joint>
    <actuator name="FR_wheel">
      <mechanicalReduction>1</mechanicalReduction>
    </actuator>
  </transmission>
  <transmission name="tranRL_wheel">
    <type>transmission_interface/SimpleTransmission</type>
    <joint name="RL_wheel_joint">
      <hardwareInterface>hardware_interface/EffortJointInterface</hardwareInterface>
    </joint>
    <actuator name="RL_wheel">
      <mechanicalReduction>1</mechanicalReduction>
    </actuator>
  </transmission>
  <transmission name="tranRR_wheel">
    <type>transmission_interface/SimpleTransmission</type>
    <joint name="RR_wheel_joint">
      <hardwareInterface>hardware_interface/EffortJointInterface</hardwareInterface>
    </joint>
    <actuator name="RR_wheel">
      <mechanicalReduction>1</mechanicalReduction>
    </actuator>
  </transmission>
  <joint name="velodyne2_base_mount_joint" type="fixed">
    <origin rpy="0 0 0" xyz="0.5 0 0.5"/>
    <parent link="base_link"/>
    <child link="velodyne2_base_link"/>
  </joint>
  <link name="velodyne2_base_link">
    <inertial>
      <mass value="1.0"/>
      <origin xyz="0 0 0.07212"/>
      <inertia ixx="0.002188947025" ixy="0" ixz="0" iyy="0.002188947025" iyz="0" izz="0.00091036445"/>
    </inertial>
    <visual>
      <geometry>
        <mesh filename="package://velodyne_description/meshes/HDL32E_base.dae"/>
      </geometry>
    </visual>
    <collision>
      <origin rpy="0 0 0" xyz="0 0 0.07212"/>
      <geometry>
        <cylinder length="0.14424" radius="0.04267"/>
      </geometry>
    </collision>
  </link>
  <joint name="velodyne2_base_scan_joint" type="fixed">
    <origin rpy="0 0 0" xyz="0 0 0.09081"/>
    <parent link="velodyne2_base_link"/>
    <child link="velodyne2"/>
  </joint>
  <link name="velodyne2">
    <inertial>
      <mass value="0.01"/>
      <origin xyz="0 0 0"/>
      <inertia ixx="1e-7" ixy="0" ixz="0" iyy="1e-7" iyz="0" izz="1e-7"/>
    </inertial>
    <visual>
      <origin rpy="0 0 0" xyz="0 0 -0.09081"/>
      <geometry>
        <mesh filename="package://velodyne_description/meshes/HDL32E_scan.dae"/>
      </geometry>
    </visual>
  </link>
  <!-- Gazebo requires the velodyne_gazebo_plugins package -->
  <gazebo reference="velodyne2">
    <sensor name="velodyne2-HDL32E" type="ray">
      <pose>0 0 0 0 0 0</pose>
      <visualize>false</visualize>
      <update_rate>10</update_rate>
      <ray>
        <scan>
          <horizontal>
            <samples>220</samples>
            <resolution>1</resolution>
            <min_angle>-3.14159265359</min_angle>
            <max_angle>3.14159265359</max_angle>
          </horizontal>
          <vertical>
            <samples>32</samples>
            <resolution>1</resolution>
            <min_angle>-0.535292481587</min_angle>
            <max_angle> 0.186226631188</max_angle>
          </vertical>
        </scan>
        <range>
          <min>0.3</min>
          <max>131.0</max>
          <resolution>0.001</resolution>
        </range>
        <noise>
          <type>gaussian</type>
          <mean>0.0</mean>
          <stddev>0.0</stddev>
        </noise>
      </ray>
      <plugin filename="libgazebo_ros_velodyne_laser.so" name="gazebo_ros_laser_controller">
        <topicName>/velodyne_points2</topicName>
        <frameName>velodyne2</frameName>
        <min_range>0.9</min_range>
        <max_range>130.0</max_range>
        <gaussianNoise>0.008</gaussianNoise>
      </plugin>
    </sensor>
  </gazebo>
  <plugin filename="libgazebo_motor_model.so" name="front_right_motor_model">
    <robotNamespace/>
    <jointName>FR_prop_joint</jointName>
    <linkName>FR_prop_link</linkName>
    <turningDirection>ccw</turningDirection>
    <timeConstantUp>0.0125</timeConstantUp>
    <timeConstantDown>0.025</timeConstantDown>
    <maxRotVelocity>1100</maxRotVelocity>
    <motorConstant>5.84e-06</motorConstant>
    <momentConstant>0.06</momentConstant>
    <commandSubTopic>/gazebo/command/motor_speed</commandSubTopic>
    <motorNumber>0</motorNumber>
    <rotorDragCoefficient>0.000175</rotorDragCoefficient>
    <rollingMomentCoefficient>1e-06</rollingMomentCoefficient>
    <motorSpeedPubTopic>/motor_speed/0</motorSpeedPubTopic>
    <rotorVelocitySlowdownSim>10</rotorVelocitySlowdownSim>
  </plugin>
  <plugin filename="libgazebo_motor_model.so" name="back_left_motor_model">
    <robotNamespace/>
    <jointName>RL_prop_joint</jointName>
    <linkName>RL_prop_link</linkName>
    <turningDirection>ccw</turningDirection>
    <timeConstantUp>0.0125</timeConstantUp>
    <timeConstantDown>0.025</timeConstantDown>
    <maxRotVelocity>1100</maxRotVelocity>
    <motorConstant>5.84e-06</motorConstant>
    <momentConstant>0.06</momentConstant>
    <commandSubTopic>/gazebo/command/motor_speed</commandSubTopic>
    <motorNumber>1</motorNumber>
    <rotorDragCoefficient>0.000175</rotorDragCoefficient>
    <rollingMomentCoefficient>1e-06</rollingMomentCoefficient>
    <motorSpeedPubTopic>/motor_speed/1</motorSpeedPubTopic>
    <rotorVelocitySlowdownSim>10</rotorVelocitySlowdownSim>
  </plugin>
  <plugin filename="libgazebo_motor_model.so" name="front_left_motor_model">
    <robotNamespace/>
    <jointName>FR_prop_joint</jointName>
    <linkName>FR_prop_link</linkName>
    <turningDirection>cw</turningDirection>
    <timeConstantUp>0.0125</timeConstantUp>
    <timeConstantDown>0.025</timeConstantDown>
    <maxRotVelocity>1100</maxRotVelocity>
    <motorConstant>5.84e-06</motorConstant>
    <momentConstant>0.06</momentConstant>
    <commandSubTopic>/gazebo/command/motor_speed</commandSubTopic>
    <motorNumber>2</motorNumber>
    <rotorDragCoefficient>0.000175</rotorDragCoefficient>
    <rollingMomentCoefficient>1e-06</rollingMomentCoefficient>
    <motorSpeedPubTopic>/motor_speed/2</motorSpeedPubTopic>
    <rotorVelocitySlowdownSim>10</rotorVelocitySlowdownSim>
  </plugin>
  <plugin filename="libgazebo_motor_model.so" name="back_right_motor_model">
    <robotNamespace/>
    <jointName>RR_prop_joint</jointName>
    <linkName>RR_prop_link</linkName>
    <jointName>rotor_3_joint</jointName>
    <linkName>rotor_3</linkName>
    <turningDirection>cw</turningDirection>
    <timeConstantUp>0.0125</timeConstantUp>
    <timeConstantDown>0.025</timeConstantDown>
    <maxRotVelocity>1100</maxRotVelocity>
    <motorConstant>5.84e-06</motorConstant>
    <momentConstant>0.06</momentConstant>
    <commandSubTopic>/gazebo/command/motor_speed</commandSubTopic>
    <motorNumber>3</motorNumber>
    <rotorDragCoefficient>0.000175</rotorDragCoefficient>
    <rollingMomentCoefficient>1e-06</rollingMomentCoefficient>
    <motorSpeedPubTopic>/motor_speed/3</motorSpeedPubTopic>
    <rotorVelocitySlowdownSim>10</rotorVelocitySlowdownSim>
  </plugin>
  <link name="gps0_link">
    <inertial>
      <origin rpy="0 0 0" xyz="0 0 0"/>
      <mass value="0.01"/>
      <inertia ixx="2.1733e-06" ixy="0" ixz="0" iyy="2.1733e-06" iyz="0" izz="1.8e-07"/>
    </inertial>
    <visual name="visual">
      <geometry>
        <cylinder length="0.002" radius="0.01"/>
      </geometry>
    </visual>
    <sensor name="gps" type="gps">
      <pose>0 0 0 0 0 0</pose>
      <plugin filename="libgazebo_gps_plugin.so" name="gps_plugin">
        <robotNamespace/>
        <gpsNoise>1</gpsNoise>
        <gpsXYRandomWalk>2.0</gpsXYRandomWalk>
        <gpsZRandomWalk>4.0</gpsZRandomWalk>
        <gpsXYNoiseDensity>0.0002</gpsXYNoiseDensity>
        <gpsZNoiseDensity>0.0004</gpsZNoiseDensity>
        <gpsVXYNoiseDensity>0.2</gpsVXYNoiseDensity>
        <gpsVZNoiseDensity>0.4</gpsVZNoiseDensity>
      </plugin>
    </sensor>
  </link>
  <joint name="gps0_joint" type="fixed">
    <parent link="base_link"/>
    <child link="gps0_link"/>
    <origin rpy="0 0 0" xyz="0.5 0 0.7"/>
    <axis xyz="0 0 0"/>
  </joint>
  <plugin filename="libgazebo_groundtruth_plugin.so" name="groundtruth_plugin">
    <robotNamespace/>
  </plugin>
  <plugin filename="libgazebo_magnetometer_plugin.so" name="magnetometer_plugin">
    <robotNamespace/>
    <pubRate>100</pubRate>
    <noiseDensity>0.0004</noiseDensity>
    <randomWalk>6.4e-06</randomWalk>
    <biasCorrelationTime>600</biasCorrelationTime>
    <magTopic>/mag</magTopic>
  </plugin>
  <plugin filename="libgazebo_barometer_plugin.so" name="barometer_plugin">
    <robotNamespace/>
    <pubRate>50</pubRate>
    <baroTopic>/baro</baroTopic>
    <baroDriftPaPerSec>0</baroDriftPaPerSec>
  </plugin>
  <plugin filename="libgazebo_mavlink_interface.so" name="mavlink_interface">
    <robotNamespace/>
    <imuSubTopic>/imu</imuSubTopic>
    <magSubTopic>/mag</magSubTopic>
    <baroSubTopic>/baro</baroSubTopic>
    <mavlink_addr>INADDR_ANY</mavlink_addr>
    <mavlink_tcp_port>4560</mavlink_tcp_port>
    <mavlink_udp_port>14560</mavlink_udp_port>
    <serialEnabled>0</serialEnabled>
    <serialDevice>/dev/ttyACM0</serialDevice>
    <baudRate>921600</baudRate>
    <qgc_addr>INADDR_ANY</qgc_addr>
    <qgc_udp_port>14550</qgc_udp_port>
    <sdk_addr>INADDR_ANY</sdk_addr>
    <sdk_udp_port>14540</sdk_udp_port>
    <hil_mode>0</hil_mode>
    <hil_state_level>0</hil_state_level>
    <send_vision_estimation>0</send_vision_estimation>
    <send_odometry>1</send_odometry>
    <enable_lockstep>1</enable_lockstep>
    <use_tcp>1</use_tcp>
    <motorSpeedCommandPubTopic>/gazebo/command/motor_speed</motorSpeedCommandPubTopic>
    <control_channels>
      <channel name="rotor1">
        <input_index>0</input_index>
        <input_offset>0</input_offset>
        <input_scaling>1000</input_scaling>
        <zero_position_disarmed>0</zero_position_disarmed>
        <zero_position_armed>100</zero_position_armed>
        <joint_control_type>velocity</joint_control_type>
      </channel>
      <channel name="rotor2">
        <input_index>1</input_index>
        <input_offset>0</input_offset>
        <input_scaling>1000</input_scaling>
        <zero_position_disarmed>0</zero_position_disarmed>
        <zero_position_armed>100</zero_position_armed>
        <joint_control_type>velocity</joint_control_type>
      </channel>
      <channel name="rotor3">
        <input_index>2</input_index>
        <input_offset>0</input_offset>
        <input_scaling>1000</input_scaling>
        <zero_position_disarmed>0</zero_position_disarmed>
        <zero_position_armed>100</zero_position_armed>
        <joint_control_type>velocity</joint_control_type>
      </channel>
      <channel name="rotor4">
        <input_index>3</input_index>
        <input_offset>0</input_offset>
        <input_scaling>1000</input_scaling>
        <zero_position_disarmed>0</zero_position_disarmed>
        <zero_position_armed>100</zero_position_armed>
        <joint_control_type>velocity</joint_control_type>
      </channel>
      <channel name="rotor5">
        <input_index>4</input_index>
        <input_offset>1</input_offset>
        <input_scaling>324.6</input_scaling>
        <zero_position_disarmed>0</zero_position_disarmed>
        <zero_position_armed>0</zero_position_armed>
        <joint_control_type>velocity</joint_control_type>
        <joint_control_pid>
          <p>0.1</p>
          <i>0</i>
          <d>0</d>
          <iMax>0.0</iMax>
          <iMin>0.0</iMin>
          <cmdMax>2</cmdMax>
          <cmdMin>-2</cmdMin>
        </joint_control_pid>
        <joint_name>zephyr_delta_wing::propeller_joint</joint_name>
      </channel>
      <channel name="rotor6">
        <input_index>5</input_index>
        <input_offset>0</input_offset>
        <input_scaling>0.524</input_scaling>
        <zero_position_disarmed>0</zero_position_disarmed>
        <zero_position_armed>0</zero_position_armed>
        <joint_control_type>position</joint_control_type>
        <joint_name>zephyr_delta_wing::flap_left_joint</joint_name>
        <joint_control_pid>
          <p>10.0</p>
          <i>0</i>
          <d>0</d>
          <iMax>0</iMax>
          <iMin>0</iMin>
          <cmdMax>20</cmdMax>
          <cmdMin>-20</cmdMin>
        </joint_control_pid>
      </channel>
      <channel name="rotor7">
        <input_index>6</input_index>
        <input_offset>0</input_offset>
        <input_scaling>0.524</input_scaling>
        <zero_position_disarmed>0</zero_position_disarmed>
        <zero_position_armed>0</zero_position_armed>
        <joint_control_type>position</joint_control_type>
        <joint_name>zephyr_delta_wing::flap_right_joint</joint_name>
        <joint_control_pid>
          <p>10.0</p>
          <i>0</i>
          <d>0</d>
          <iMax>0</iMax>
          <iMin>0</iMin>
          <cmdMax>20</cmdMax>
          <cmdMin>-20</cmdMin>
        </joint_control_pid>
      </channel>
      <channel name="rotor8">
        <input_index>7</input_index>
        <input_offset>0</input_offset>
        <input_scaling>0.524</input_scaling>
        <zero_position_disarmed>0</zero_position_disarmed>
        <zero_position_armed>0</zero_position_armed>
        <joint_control_type>position</joint_control_type>
      </channel>
    </control_channels>
  </plugin>
  <static>0</static>
  <plugin filename="libgazebo_imu_plugin.so" name="rotors_gazebo_imu_plugin">
    <robotNamespace/>
    <linkName>/imu_link</linkName>
    <imuTopic>/imu</imuTopic>
    <gyroscopeNoiseDensity>0.00018665</gyroscopeNoiseDensity>
    <gyroscopeRandomWalk>3.8785e-05</gyroscopeRandomWalk>
    <gyroscopeBiasCorrelationTime>1000.0</gyroscopeBiasCorrelationTime>
    <gyroscopeTurnOnBiasSigma>0.0087</gyroscopeTurnOnBiasSigma>
    <accelerometerNoiseDensity>0.00186</accelerometerNoiseDensity>
    <accelerometerRandomWalk>0.006</accelerometerRandomWalk>
    <accelerometerBiasCorrelationTime>300.0</accelerometerBiasCorrelationTime>
    <accelerometerTurnOnBiasSigma>0.196</accelerometerTurnOnBiasSigma>
  </plugin>
  <link name="base_link">
    <inertial>
      <origin rpy="0 0 0" xyz="-0.146429923355639 4.6141216103468E-06 0.306922339438389"/>
      <mass value="72.4585171289715"/>
      <inertia ixx="1.61550819650369" ixy="-3.16188395392895E-05" ixz="0.0620334640597006" iyy="2.74355272384867" iyz="-0.00648256065496445" izz="3.23450546919946"/>
    </inertial>
    <visual>
      <origin rpy="0 0 0" xyz="0 0 0"/>
      <geometry>
        <mesh filename="package://flying_car_urdf/meshes/base_link.STL"/>
      </geometry>
      <material name="">
        <color rgba="0.752941176470588 0.752941176470588 0.752941176470588 1"/>
      </material>
    </visual>
    <collision>
      <origin rpy="0 0 0" xyz="0 0 0"/>
      <geometry>
        <mesh filename="package://flying_car_urdf/meshes/base_link.STL"/>
      </geometry>
    </collision>
  </link>
  <link name="FL_arm_link">
    <inertial>
      <origin rpy="0 0 0" xyz="0.405693257704713 0.0031481565089142 0.107253489414463"/>
      <mass value="3.89447230721183"/>
      <inertia ixx="0.00764950499387066" ixy="7.20024305750638E-05" ixz="-2.12112386887157E-07" iyy="0.0330920443295484" iyz="-1.37630637299853E-08" izz="0.0321291032185021"/>
    </inertial>
    <visual>
      <origin rpy="0 0 0" xyz="0 0 0"/>
      <geometry>
        <mesh filename="package://flying_car_urdf/meshes/FL_arm_link.STL"/>
      </geometry>
      <material name="">
        <color rgba="0.752941176470588 0.752941176470588 0.752941176470588 1"/>
      </material>
    </visual>
    <collision>
      <origin rpy="0 0 0" xyz="0 0 0"/>
      <geometry>
        <mesh filename="package://flying_car_urdf/meshes/FL_arm_link.STL"/>
      </geometry>
    </collision>
  </link>
  <joint name="FL_arm_joint" type="revolute">
    <origin rpy="0 0 1.5707963267949" xyz="0.940000000000001 0.48 0.339999999999999"/>
    <parent link="base_link"/>
    <child link="FL_arm_link"/>
    <axis xyz="0 0 -1"/>
    <limit effort="100" lower="-1.57" upper="0" velocity="1"/>
  </joint>
  <link name="FL_prop_link">
    <inertial>
      <origin rpy="0 0 0" xyz="7.9164959032596E-09 -0.00186087352819841 -1.45022256425875E-08"/>
      <mass value="1.00633319200359"/>
      <inertia ixx="0.0495943276929438" ixy="5.12014239400693E-11" ixz="0.0777130986532108" iyy="0.173195440429717" iyz="1.30510821163399E-10" izz="0.123701063238782"/>
    </inertial>
    <visual>
      <origin rpy="0 0 0" xyz="0 0 0"/>
      <geometry>
        <mesh filename="package://flying_car_urdf/meshes/FL_prop_link.STL"/>
      </geometry>
      <material name="">
        <color rgba="1 1 1 1"/>
      </material>
    </visual>
    <collision>
      <origin rpy="0 0 0" xyz="0 0 0"/>
      <geometry>
        <mesh filename="package://flying_car_urdf/meshes/FL_prop_link.STL"/>
      </geometry>
    </collision>
  </link>
  <joint name="FL_prop_joint" type="continuous">
    <origin rpy="1.5708 0 0" xyz="0.76505 0 0.254"/>
    <parent link="FL_arm_link"/>
    <child link="FL_prop_link"/>
    <axis xyz="0 1 0"/>
  </joint>
  <link name="FR_arm_link">
    <inertial>
      <origin rpy="0 0 0" xyz="0.405693257704711 -0.00725348941446158 -0.00314828941180689"/>
      <mass value="3.89447230721182"/>
      <inertia ixx="0.00764950499387065" ixy="2.12112386890709E-07" ixz="-7.20021868805378E-05" iyy="0.0321291032185021" iyz="1.37630637386484E-08" izz="0.0330920443295484"/>
    </inertial>
    <visual>
      <origin rpy="0 0 0" xyz="0 0 0"/>
      <geometry>
        <mesh filename="package://flying_car_urdf/meshes/FR_arm_link.STL"/>
      </geometry>
      <material name="">
        <color rgba="0.752941176470588 0.752941176470588 0.752941176470588 1"/>
      </material>
    </visual>
    <collision>
      <origin rpy="0 0 0" xyz="0 0 0"/>
      <geometry>
        <mesh filename="package://flying_car_urdf/meshes/FR_arm_link.STL"/>
      </geometry>
    </collision>
  </link>
  <joint name="FR_arm_joint" type="revolute">
    <origin rpy="-1.5708 0 -1.5708" xyz="0.94 -0.48 0.44"/>
    <parent link="base_link"/>
    <child link="FR_arm_link"/>
    <axis xyz="0 -1 0"/>
    <limit effort="100" lower="-1.57" upper="0" velocity="1"/>
  </joint>
  <link name="FR_prop_link">
    <inertial>
      <origin rpy="0 0 0" xyz="-1.95864401566527E-07 -0.00186086168514299 1.01704304089623E-07"/>
      <mass value="1.00636259561687"/>
      <inertia ixx="0.0395701881672427" ixy="4.88903964209589E-10" ixz="0.0720874245458485" iyy="0.173211048789436" iyz="-1.15461644657509E-10" izz="0.133740813319805"/>
    </inertial>
    <visual>
      <origin rpy="0 0 0" xyz="0 0 0"/>
      <geometry>
        <mesh filename="package://flying_car_urdf/meshes/FR_prop_link.STL"/>
      </geometry>
      <material name="">
        <color rgba="1 1 1 1"/>
      </material>
    </visual>
    <collision>
      <origin rpy="0 0 0" xyz="0 0 0"/>
      <geometry>
        <mesh filename="package://flying_car_urdf/meshes/FR_prop_link.STL"/>
      </geometry>
    </collision>
  </link>
  <joint name="FR_prop_joint" type="continuous">
    <origin rpy="0 0 3.14159265358979" xyz="0.765051653365603 -0.154000000000011 0"/>
    <parent link="FR_arm_link"/>
    <child link="FR_prop_link"/>
    <axis xyz="0 1 0"/>
  </joint>
  <link name="RR_arm_link">
    <inertial>
      <origin rpy="0 0 0" xyz="0.405693257704711 0.00314815650891492 0.107253489414463"/>
      <mass value="3.89447230721182"/>
      <inertia ixx="0.00764950499387065" ixy="7.20024305750679E-05" ixz="-2.1211238688973E-07" iyy="0.0330920443295484" iyz="-1.37630637350729E-08" izz="0.0321291032185021"/>
    </inertial>
    <visual>
      <origin rpy="0 0 0" xyz="0 0 0"/>
      <geometry>
        <mesh filename="package://flying_car_urdf/meshes/RR_arm_link.STL"/>
      </geometry>
      <material name="">
        <color rgba="0.752941176470588 0.752941176470588 0.752941176470588 1"/>
      </material>
    </visual>
    <collision>
      <origin rpy="0 0 0" xyz="0 0 0"/>
      <geometry>
        <mesh filename="package://flying_car_urdf/meshes/RR_arm_link.STL"/>
      </geometry>
    </collision>
  </link>
  <joint name="RR_arm_joint" type="revolute">
    <origin rpy="0 0 -1.5708" xyz="-0.94 -0.48 0.34"/>
    <parent link="base_link"/>
    <child link="RR_arm_link"/>
    <axis xyz="0 0 -1"/>
    <limit effort="100" lower="-1.57" upper="0" velocity="1"/>
  </joint>
  <link name="RR_prop_link">
    <inertial>
      <origin rpy="0 0 0" xyz="2.17005934749492E-09 -0.00186087212280439 -8.24081997086168E-09"/>
      <mass value="1.00633311458426"/>
      <inertia ixx="0.0495943271195099" ixy="-5.63368805909919E-11" ixz="0.0777130981431345" iyy="0.173195439404083" iyz="2.46588541774348E-10" izz="0.123701062736267"/>
    </inertial>
    <visual>
      <origin rpy="0 0 0" xyz="0 0 0"/>
      <geometry>
        <mesh filename="package://flying_car_urdf/meshes/RR_prop_link.STL"/>
      </geometry>
      <material name="">
        <color rgba="1 1 1 1"/>
      </material>
    </visual>
    <collision>
      <origin rpy="0 0 0" xyz="0 0 0"/>
      <geometry>
        <mesh filename="package://flying_car_urdf/meshes/RR_prop_link.STL"/>
      </geometry>
    </collision>
  </link>
  <joint name="RR_prop_joint" type="continuous">
    <origin rpy="1.5707963267949 0 3.14159265358979" xyz="0.765051653365595 0 0.254000000000003"/>
    <parent link="RR_arm_link"/>
    <child link="RR_prop_link"/>
    <axis xyz="0 1 0"/>
  </joint>
  <link name="RL_arm_link">
    <inertial>
      <origin rpy="0 0 0" xyz="0.40569325770471 0.00725348941446136 0.00314828941180623"/>
      <mass value="3.89447230721181"/>
      <inertia ixx="0.00764950499387061" ixy="-2.12112386866559E-07" ixz="7.20021868805221E-05" iyy="0.032129103218502" iyz="1.37630637374215E-08" izz="0.0330920443295484"/>
    </inertial>
    <visual>
      <origin rpy="0 0 0" xyz="0 0 0"/>
      <geometry>
        <mesh filename="package://flying_car_urdf/meshes/RL_arm_link.STL"/>
      </geometry>
      <material name="">
        <color rgba="0.752941176470588 0.752941176470588 0.752941176470588 1"/>
      </material>
    </visual>
    <collision>
      <origin rpy="0 0 0" xyz="0 0 0"/>
      <geometry>
        <mesh filename="package://flying_car_urdf/meshes/RL_arm_link.STL"/>
      </geometry>
    </collision>
  </link>
  <joint name="RL_arm_joint" type="revolute">
    <origin rpy="1.5708 0 1.5708" xyz="-0.94 0.48 0.44"/>
    <parent link="base_link"/>
    <child link="RL_arm_link"/>
    <axis xyz="0 1 0"/>
    <limit effort="100" lower="-1.57" upper="0" velocity="1"/>
  </joint>
  <link name="RL_prop_link">
    <inertial>
      <origin rpy="0 0 0" xyz="-1.90695036650368E-07 -0.00186086500205929 9.97787533985051E-08"/>
      <mass value="1.00636280361878"/>
      <inertia ixx="0.0395701883931864" ixy="5.37299574939007E-10" ixz="0.0720874251910353" iyy="0.173211051383078" iyz="-1.36539842148325E-10" izz="0.133740815794897"/>
    </inertial>
    <visual>
      <origin rpy="0 0 0" xyz="0 0 0"/>
      <geometry>
        <mesh filename="package://flying_car_urdf/meshes/RL_prop_link.STL"/>
      </geometry>
      <material name="">
        <color rgba="1 1 1 1"/>
      </material>
    </visual>
    <collision>
      <origin rpy="0 0 0" xyz="0 0 0"/>
      <geometry>
        <mesh filename="package://flying_car_urdf/meshes/RL_prop_link.STL"/>
      </geometry>
    </collision>
  </link>
  <joint name="RL_prop_joint" type="continuous">
    <origin rpy="0 0 0" xyz="0.765051653365595 0.154000000000009 0"/>
    <parent link="RL_arm_link"/>
    <child link="RL_prop_link"/>
    <axis xyz="0 1 0"/>
  </joint>
  <link name="FR_steer_link">
    <inertial>
      <origin rpy="0 0 0" xyz="-2.22044604925031E-16 1.11022302462516E-16 -0.0452127836143312"/>
      <mass value="0.230273438117984"/>
      <inertia ixx="0.000349256798258404" ixy="1.45518192075896E-14" ixz="-7.92477996108057E-19" iyy="0.000450897154400186" iyz="1.54271030766644E-20" izz="0.000182392582849012"/>
    </inertial>
    <visual>
      <origin rpy="0 0 0" xyz="0 0 0"/>
      <geometry>
        <mesh filename="package://flying_car_urdf/meshes/FR_steer_link.STL"/>
      </geometry>
      <material name="">
        <color rgba="0.752941176470588 0.752941176470588 0.752941176470588 1"/>
      </material>
    </visual>
    <collision>
      <origin rpy="0 0 0" xyz="0 0 0"/>
      <geometry>
        <mesh filename="package://flying_car_urdf/meshes/FR_steer_link.STL"/>
      </geometry>
    </collision>
  </link>
  <joint name="FR_steer_joint" type="revolute">
    <origin rpy="0 0 0" xyz="0.707 -0.308 0.15"/>
    <parent link="base_link"/>
    <child link="FR_steer_link"/>
    <axis xyz="0 0 1"/>
    <limit effort="1" lower="-1.57" upper="1.57" velocity="1"/>
  </joint>
  <link name="FR_wheel_link">
    <inertial>
      <origin rpy="0 0 0" xyz="-1.11022302462516E-16 -1.11022302462516E-16 0"/>
      <mass value="1.84219192629543"/>
      <inertia ixx="0.0177302468286368" ixy="-4.28723099915728E-19" ixz="2.20679460797186E-18" iyy="0.00925790244280525" iyz="-3.12343399300023E-18" izz="0.00925790244280525"/>
    </inertial>
    <visual>
      <origin rpy="0 0 0" xyz="0 0 0"/>
      <geometry>
        <mesh filename="package://flying_car_urdf/meshes/FR_wheel_link.STL"/>
      </geometry>
      <material name="">
        <color rgba="0.647058823529412 0.619607843137255 0.588235294117647 1"/>
      </material>
    </visual>
    <collision>
      <origin rpy="0 0 0" xyz="0 0 0"/>
      <geometry>
        <mesh filename="package://flying_car_urdf/meshes/FR_wheel_link.STL"/>
      </geometry>
      <friction>
        <ode>
          <mu>0.68</mu>
          <mu2>0.8</mu2>
        </ode>
      </friction>
    </collision>
  </link>
  <joint name="FR_wheel_joint" type="continuous">
    <origin rpy="1.5707963267949 0 1.5707963267949" xyz="0 0 -0.145000000000282"/>
    <parent link="FR_steer_link"/>
    <child link="FR_wheel_link"/>
    <axis xyz="1 0 0"/>
  </joint>
  <link name="FL_steer_link">
    <inertial>
      <origin rpy="0 0 0" xyz="0 2.22044604925031E-16 -0.0452127836143308"/>
      <mass value="0.230273438117982"/>
      <inertia ixx="0.000349256798258392" ixy="1.45517583247674E-14" ixz="1.39565796343945E-19" iyy="0.000450897154400175" iyz="2.4253803330348E-20" izz="0.000182392582849013"/>
    </inertial>
    <visual>
      <origin rpy="0 0 0" xyz="0 0 0"/>
      <geometry>
        <mesh filename="package://flying_car_urdf/meshes/FL_steer_link.STL"/>
      </geometry>
      <material name="">
        <color rgba="0.752941176470588 0.752941176470588 0.752941176470588 1"/>
      </material>
    </visual>
    <collision>
      <origin rpy="0 0 0" xyz="0 0 0"/>
      <geometry>
        <mesh filename="package://flying_car_urdf/meshes/FL_steer_link.STL"/>
      </geometry>
    </collision>
  </link>
  <joint name="FL_steer_joint" type="revolute">
    <origin rpy="0 0 0" xyz="0.707 0.308 0.15"/>
    <parent link="base_link"/>
    <child link="FL_steer_link"/>
    <axis xyz="0 0 1"/>
    <limit effort="1" lower="-1.57" upper="1.57" velocity="1"/>
  </joint>
  <link name="FL_wheel_link">
    <inertial>
      <origin rpy="0 0 0" xyz="-2.22044604925031E-16 -1.11022302462516E-16 2.22044604925031E-16"/>
      <mass value="1.84219192629543"/>
      <inertia ixx="0.0177302468286368" ixy="5.85379655277248E-20" ixz="3.05830316111449E-18" iyy="0.00925790244280525" iyz="-3.92719505446036E-18" izz="0.00925790244280525"/>
    </inertial>
    <visual>
      <origin rpy="0 0 0" xyz="0 0 0"/>
      <geometry>
        <mesh filename="package://flying_car_urdf/meshes/FL_wheel_link.STL"/>
      </geometry>
      <material name="">
        <color rgba="0.647058823529412 0.619607843137255 0.588235294117647 1"/>
      </material>
    </visual>
    <collision>
      <origin rpy="0 0 0" xyz="0 0 0"/>
      <geometry>
        <mesh filename="package://flying_car_urdf/meshes/FL_wheel_link.STL"/>
      </geometry>
      <friction>
        <ode>
          <mu>0.68</mu>
          <mu2>0.8</mu2>
        </ode>
      </friction>
    </collision>
  </link>
  <joint name="FL_wheel_joint" type="continuous">
    <origin rpy="1.5707963267949 0 1.5707963267949" xyz="0 0 -0.144999999999987"/>
    <parent link="FL_steer_link"/>
    <child link="FL_wheel_link"/>
    <axis xyz="-1 0 0"/>
  </joint>
  <link name="RR_steer_link">
    <inertial>
      <origin rpy="0 0 0" xyz="3.88578058618805E-16 1.11022302462516E-16 -0.045212783614331"/>
      <mass value="0.230273438117983"/>
      <inertia ixx="0.000349256798258397" ixy="1.45517338150183E-14" ixz="2.46152613174949E-19" iyy="0.000450897154400179" iyz="3.50515752367294E-22" izz="0.000182392582849012"/>
    </inertial>
    <visual>
      <origin rpy="0 0 0" xyz="0 0 0"/>
      <geometry>
        <mesh filename="package://flying_car_urdf/meshes/RR_steer_link.STL"/>
      </geometry>
      <material name="">
        <color rgba="0.752941176470588 0.752941176470588 0.752941176470588 1"/>
      </material>
    </visual>
    <collision>
      <origin rpy="0 0 0" xyz="0 0 0"/>
      <geometry>
        <mesh filename="package://flying_car_urdf/meshes/RR_steer_link.STL"/>
      </geometry>
    </collision>
  </link>
  <joint name="RR_steer_joint" type="revolute">
    <origin rpy="0 0 0" xyz="-0.707 -0.308 0.15"/>
    <parent link="base_link"/>
    <child link="RR_steer_link"/>
    <axis xyz="0 0 1"/>
    <limit effort="0" lower="0" upper="0" velocity="0"/>
  </joint>
  <link name="RR_wheel_link">
    <inertial>
      <origin rpy="0 0 0" xyz="0 0 -1.11022302462516E-16"/>
      <mass value="1.84219192629543"/>
      <inertia ixx="0.0177302468286368" ixy="-1.19673225549615E-18" ixz="9.76883033040924E-19" iyy="0.00925790244280525" iyz="-2.48053598603422E-18" izz="0.00925790244280525"/>
    </inertial>
    <visual>
      <origin rpy="0 0 0" xyz="0 0 0"/>
      <geometry>
        <mesh filename="package://flying_car_urdf/meshes/RR_wheel_link.STL"/>
      </geometry>
      <material name="">
        <color rgba="0.647058823529412 0.619607843137255 0.588235294117647 1"/>
      </material>
    </visual>
    <collision>
      <origin rpy="0 0 0" xyz="0 0 0"/>
      <geometry>
        <mesh filename="package://flying_car_urdf/meshes/RR_wheel_link.STL"/>
      </geometry>
      <friction>
        <ode>
          <mu>0.68</mu>
          <mu2>0.8</mu2>
        </ode>
      </friction>
    </collision>
  </link>
  <joint name="RR_wheel_joint" type="continuous">
    <origin rpy="1.5707963267949 0 1.5707963267949" xyz="0 0 -0.145"/>
    <parent link="RR_steer_link"/>
    <child link="RR_wheel_link"/>
    <axis xyz="1 0 0"/>
  </joint>
  <link name="RL_steer_link">
    <inertial>
      <origin rpy="0 0 0" xyz="4.44089209850063E-16 -4.44089209850063E-16 -0.0452127836146745"/>
      <mass value="0.230273438117982"/>
      <inertia ixx="0.000349256798258395" ixy="1.45516390193479E-14" ixz="-2.9833008345631E-20" iyy="0.000450897154400177" iyz="3.9950109397287E-20" izz="0.000182392582849012"/>
    </inertial>
    <visual>
      <origin rpy="0 0 0" xyz="0 0 0"/>
      <geometry>
        <mesh filename="package://flying_car_urdf/meshes/RL_steer_link.STL"/>
      </geometry>
      <material name="">
        <color rgba="0.752941176470588 0.752941176470588 0.752941176470588 1"/>
      </material>
    </visual>
    <collision>
      <origin rpy="0 0 0" xyz="0 0 0"/>
      <geometry>
        <mesh filename="package://flying_car_urdf/meshes/RL_steer_link.STL"/>
      </geometry>
    </collision>
  </link>
  <joint name="RL_steer_joint" type="revolute">
    <origin rpy="0 0 0" xyz="-0.707 0.307999999999994 0.150000000000006"/>
    <parent link="base_link"/>
    <child link="RL_steer_link"/>
    <axis xyz="0 0 1"/>
    <limit effort="0" lower="0" upper="0" velocity="0"/>
  </joint>
  <link name="RL_wheel_link">
    <inertial>
      <origin rpy="0 0 0" xyz="-2.22044604925031E-16 0 -5.55111512312578E-17"/>
      <mass value="1.84219192629543"/>
      <inertia ixx="0.0177302468286368" ixy="1.75740894616314E-19" ixz="-3.86956107926909E-18" iyy="0.00925790244280525" iyz="-1.63877052492066E-18" izz="0.00925790244280525"/>
    </inertial>
    <visual>
      <origin rpy="0 0 0" xyz="0 0 0"/>
      <geometry>
        <mesh filename="package://flying_car_urdf/meshes/RL_wheel_link.STL"/>
      </geometry>
      <material name="">
        <color rgba="0.647058823529412 0.619607843137255 0.588235294117647 1"/>
      </material>
    </visual>
    <collision>
      <origin rpy="0 0 0" xyz="0 0 0"/>
      <geometry>
        <mesh filename="package://flying_car_urdf/meshes/RL_wheel_link.STL"/>
      </geometry>
      <friction>
        <ode>
          <mu>0.68</mu>
          <mu2>0.8</mu2>
        </ode>
      </friction>
    </collision>
  </link>
  <joint name="RL_wheel_joint" type="continuous">
    <origin rpy="1.5707963267949 0 1.5707963267949" xyz="0 0.000499999999971967 -0.145000000000341"/>
    <parent link="RL_steer_link"/>
    <child link="RL_wheel_link"/>
    <axis xyz="1 0 0"/>
  </joint>
</robot>

